const p = new Promise((resolve, reject) => {
  setTimeout(() => {
    reject("--- Oops ---");
    resolve('>>> Success! <<<');
  }, 2000);
});

p.then((message) => {
  console.log('Promise resolved successfully! ðŸ˜€');
  console.log(message);
}).catch((err) => {
  console.log('Promise rejected ðŸ˜ž');
  console.log(err);
}).finally(() => {
  console.log('All done!')
});

// **Problems to solve**

// **1)** What happens when a promise is rejected? Test it by calling `reject()`

// **2)** What happens when you call both `resolve` and `reject`? Test this.

// **3)** Does the order matter you call resolve and reject matter? Test this. 

// **4)** What happens if you call `resolve` or `reject` more than once? Test this out for yourself.